Workbook

Sheet AIDS A
A1: R. M. K. COLLEGE OF ENGINEERING AND TECHNOLOGY
A2: R. S. M NAGAR, PUDUVOYAL - 601 206
A3: Department of Science and Humanities
A4: I Semester B.E (Academic Year : 2025-26)
A5: Unit Test - II Result Analysis
A6: Branch & Section:AIDS - A
A7: Sl. No. | B7: Reg. No. | C7: Name | D7: G / M | E7: D/H | F7: Girl / Boy | G7: Cut off | H7: Maths | I7: Chem | J7: C++ | K7: SDP | L7: DPSD | M7: GPA | N7: No. of subjects failed | P7: absentees | Q7: Attendance
A8: 1 | B8: 111625201001 | C8: ABIJITH G S | D8: M | E8: H | F8: M | H8: A | I8: A | J8: 63 | K8: 30 | L8: 80 | M8: =sum(H8:L8)/5 -> 34.6 | N8: =((COUNTIF((H8:L8),"<50"))+(COUNTIF((H8:L8),"=A"))) -> 3 | O8: =IF((N8<1),"0","1") -> 1 | P8: =COUNTIF((H8:L8),"=A") -> 2 | Q8: 91
A9: 2 | B9: 111625201002 | C9: ABISHEK M | D9: G | E9: H | F9: M | H9: 67 | I9: 53.333333 | J9: 53 | K9: 60 | L9: 63 | M9: =sum(H9:L9)/5 -> 59.266667 | N9: =((COUNTIF((H9:L9),"<50"))+(COUNTIF((H9:L9),"=A"))) -> 0 | O9: =IF((N9<1),"0","1") -> 0 | P9: =COUNTIF((H9:L9),"=A") -> 0 | Q9: 100
A10: 3 | B10: 111625201003 | C10: ADDIPALLI LAHITH VARMA | D10: M | E10: H | F10: M | H10: 50 | I10: 50 | J10: 20 | K10: 30 | L10: 13 | M10: =sum(H10:L10)/5 -> 32.6 | N10: =((COUNTIF((H10:L10),"<50"))+(COUNTIF((H10:L10),"=A"))) -> 3 | O10: =IF((N10<1),"0","1") -> 1 | P10: =COUNTIF((H10:L10),"=A") -> 0 | Q10: 100
A11: 4 | B11: 111625201004 | C11: AJAY R V | D11: M | E11: D | F11: M | H11: 53 | I11: 73.333333 | J11: 63 | K11: 73 | L11: 67 | M11: =sum(H11:L11)/5 -> 65.866667 | N11: =((COUNTIF((H11:L11),"<50"))+(COUNTIF((H11:L11),"=A"))) -> 0 | O11: =IF((N11<1),"0","1") -> 0 | P11: =COUNTIF((H11:L11),"=A") -> 0 | Q11: 98
A12: 5 | B12: 111625201005 | C12: AKSHAYA K | D12: G | E12: D | F12: F | H12: 67 | I12: 70 | J12: 80 | K12: 77 | L12: 80 | M12: =sum(H12:L12)/5 -> 74.8 | N12: =((COUNTIF((H12:L12),"<50"))+(COUNTIF((H12:L12),"=A"))) -> 0 | O12: =IF((N12<1),"0","1") -> 0 | P12: =COUNTIF((H12:L12),"=A") -> 0 | Q12: 98
A13: 6 | B13: 111625201006 | C13: AKSHAYA R | D13: M | E13: H | F13: F | H13: 53 | I13: 93.333333 | J13: 77 | K13: 53 | L13: 90 | M13: =sum(H13:L13)/5 -> 73.266667 | N13: =((COUNTIF((H13:L13),"<50"))+(COUNTIF((H13:L13),"=A"))) -> 0 | O13: =IF((N13<1),"0","1") -> 0 | P13: =COUNTIF((H13:L13),"=A") -> 0 | Q13: 100
A14: 7 | B14: 111625201007 | C14: ANAGHA SRIRAM S | D14: M | E14: D | F14: F | H14: 77 | I14: 50 | J14: 63 | K14: 30 | L14: 50 | M14: =sum(H14:L14)/5 -> 54 | N14: =((COUNTIF((H14:L14),"<50"))+(COUNTIF((H14:L14),"=A"))) -> 1 | O14: =IF((N14<1),"0","1") -> 1 | P14: =COUNTIF((H14:L14),"=A") -> 0 | Q14: 96
A15: 8 | B15: 111625201008 | C15: ANIPIREDDY LEELA VISHNU REDDY | D15: M | E15: H | F15: M | H15: 50 | I15: 36.666667 | J15: 63 | K15: 17 | L15: 57 | M15: =sum(H15:L15)/5 -> 44.733333 | N15: =((COUNTIF((H15:L15),"<50"))+(COUNTIF((H15:L15),"=A"))) -> 2 | O15: =IF((N15<1),"0","1") -> 1 | P15: =COUNTIF((H15:L15),"=A") -> 0 | Q15: 96
A16: 9 | B16: 111625201009 | C16: ANISHA LAKSHMI G S | D16: M | E16: D | F16: F | H16: 77 | I16: 86.666667 | J16: 67 | K16: 77 | L16: 93 | M16: =sum(H16:L16)/5 -> 80.133333 | N16: =((COUNTIF((H16:L16),"<50"))+(COUNTIF((H16:L16),"=A"))) -> 0 | O16: =IF((N16<1),"0","1") -> 0 | P16: =COUNTIF((H16:L16),"=A") -> 0 | Q16: 98
A17: 10 | B17: 111625201010 | C17: ARAVIND ALAGAPPAN AR | D17: G | E17: D | F17: M | H17: 60 | I17: 66.666667 | J17: 67 | K17: 51 | L17: 87 | M17: =sum(H17:L17)/5 -> 66.333333 | N17: =((COUNTIF((H17:L17),"<50"))+(COUNTIF((H17:L17),"=A"))) -> 0 | O17: =IF((N17<1),"0","1") -> 0 | P17: =COUNTIF((H17:L17),"=A") -> 0 | Q17: 96
A18: 11 | B18: 111625201011 | C18: ARCHANA ANBAZHAGAN | D18: M | E18: D | F18: F | H18: 80 | I18: 70 | J18: 20 | K18: 60 | L18: 43 | M18: =sum(H18:L18)/5 -> 54.6 | N18: =((COUNTIF((H18:L18),"<50"))+(COUNTIF((H18:L18),"=A"))) -> 2 | O18: =IF((N18<1),"0","1") -> 1 | P18: =COUNTIF((H18:L18),"=A") -> 0 | Q18: 96
A19: 12 | B19: 111625201012 | C19: AREDDULA VARSHITH KUMAR | D19: M | E19: H | F19: M | H19: 60 | I19: 50 | J19: 50 | K19: 30 | L19: 50 | M19: =sum(H19:L19)/5 -> 48 | N19: =((COUNTIF((H19:L19),"<50"))+(COUNTIF((H19:L19),"=A"))) -> 1 | O19: =IF((N19<1),"0","1") -> 1 | P19: =COUNTIF((H19:L19),"=A") -> 0 | Q19: 96
A20: 13 | B20: 111625201013 | C20: ARIGELA LIKITH SRINIVAS | D20: M | E20: H | F20: M | H20: 7 | I20: 50 | J20: 50 | K20: 50 | L20: 40 | M20: =sum(H20:L20)/5 -> 39.4 | N20: =((COUNTIF((H20:L20),"<50"))+(COUNTIF((H20:L20),"=A"))) -> 2 | O20: =IF((N20<1),"0","1") -> 1 | P20: =COUNTIF((H20:L20),"=A") -> 0 | Q20: 98
... A24: 17 | B24: 111625201017 | C24: BAGAVATHI E | D24: G | E24: H | F24: M | H24: 20 | I24: 33.333333 | J24: 17 | K24: 23 | L24: 60 | M24: =sum(H24:L24)/5 -> 30.666667 | N24: =((COUNTIF((H24:L24),"<50"))+(COUNTIF((H24:L24),"=A"))) -> 4 | O24: =IF((N24<1),"0","1") -> 1 | P24: =COUNTIF((H24:L24),"=A") -> 0 | Q24: 100
A25: 18 | B25: 111625201018 | C25: BALAJI T | D25: G | E25: H | F25: M | H25: 67 | I25: 73.333333 | J25: 83 | K25: 33 | L25: 50 | M25: =sum(H25:L25)/5 -> 61.266667 | N25: =((COUNTIF((H25:L25),"<50"))+(COUNTIF((H25:L25),"=A"))) -> 1 | Q25: 100
A26: 19 | B26: 111625201019 | C26: BENARJI M | D26: M | E26: H | F26: M | H26: 70 | I26: 50 | J26: 60 | K26: 30 | L26: 87 | M26: =sum(H26:L26)/5 -> 59.4 | N26: =((COUNTIF((H26:L26),"<50"))+(COUNTIF((H26:L26),"=A"))) -> 1 | Q26: 100
A27: 20 | B27: 111625201020 | C27: BHAVITH SAI REDDY B | D27: M | E27: H | F27: M | H27: 73 | I27: 33.333333 | J27: 57 | K27: 63 | L27: 87 | M27: =sum(H27:L27)/5 -> 62.666667 | N27: =((COUNTIF((H27:L27),"<50"))+(COUNTIF((H27:L27),"=A"))) -> 1 | Q27: 100
A28: 21 | B28: 111625201021 | C28: BHOOMIKA P | D28: G | E28: D | F28: F | H28: 90 | I28: 83.333333 | J28: 90 | K28: 80 | L28: 100 | M28: =sum(H28:L28)/5 -> 88.666667 | N28: =((COUNTIF((H28:L28),"<50"))+(COUNTIF((H28:L28),"=A"))) -> 0 | Q28: 96
A29: 22 | B29: 111625201022 | C29: BHUVANA LAKSHMI B | D29: G | E29: D | F29: F | H29: 87 | I29: 66.666667 | J29: 70 | K29: 50 | L29: 97 | M29: =sum(H29:L29)/5 -> 74.133333 | N29: =((COUNTIF((H29:L29),"<50"))+(COUNTIF((H29:L29),"=A"))) -> 0 | Q29: 94
A30: 23 | B30: 111625201023 | C30: BHUVANESWARAN R | D30: G | E30: D | F30: M | H30: 80 | I30: 86.666667 | J30: 70 | K30: 70 | L30: 67 | M30: =sum(H30:L30)/5 -> 74.733333 | N30: =((COUNTIF((H30:L30),"<50"))+(COUNTIF((H30:L30),"=A"))) -> 0 | Q30: 98
A31: 24 | B31: 111625201024 | C31: BUSIREDDY CHAITANYA | D31: M | E31: H | F31: M | H31: 60 | I31: 33.333333 | J31: 40 | K31: 50 | L31: 63 | M31: =sum(H31:L31)/5 -> 49.266667 | N31: =((COUNTIF((H31:L31),"<50"))+(COUNTIF((H31:L31),"=A"))) -> 2 | Q31: 98
A32: 25 | B32: 111625201025 | C32: CHANDRU M | D32: G | E32: H | F32: M | H32: 53 | I32: 53.333333 | J32: 33 | K32: 7 | L32: 57 | M32: =sum(H32:L32)/5 -> 40.666667 | N32: =((COUNTIF((H32:L32),"<50"))+(COUNTIF((H32:L32),"=A"))) -> 2 | Q32: 100
A33: 26 | B33: 111625201026 | C33: CHANDULURU VASAVI | D33: M | E33: H | F33: F | H33: 87 | I33: 86.666667 | J33: 63 | K33: 50 | L33: 87 | M33: =sum(H33:L33)/5 -> 74.733333 | N33: =((COUNTIF((H33:L33),"<50"))+(COUNTIF((H33:L33),"=A"))) -> 0 | Q33: 100
A34: 27 | B34: 111625201027 | C34: CHATRESH B | D34: M | E34: H | F34: M | H34: 57 | I34: 20 | J34: 70 | K34: 30 | L34: 80 | M34: =sum(H34:L34)/5 -> 51.4 | N34: =((COUNTIF((H34:L34),"<50"))+(COUNTIF((H34:L34),"=A"))) -> 2 | Q34: 87
A35: 28 | B35: 111625201028 | C35: DAKA VENKATA HARSHA VARDHAN REDDY | D35: M | E35: H | F35: M | H35: 80 | I35: 53.333333 | J35: 57 | K35: 53 | L35: 93 | M35: =sum(H35:L35)/5 -> 67.266667 | N35: =((COUNTIF((H35:L35),"<50"))+(COUNTIF((H35:L35),"=A"))) -> 0 | Q35: 98
A36: 29 | B36: 111625201029 | C36: DEEKSHITHA S M | D36: M | E36: H | F36: F | H36: 73 | I36: 73.333333 | J36: 70 | K36: 63 | L36: 80 | M36: =sum(H36:L36)/5 -> 71.866667 | N36: =((COUNTIF((H36:L36),"<50"))+(COUNTIF((H36:L36),"=A"))) -> 0 | Q36: 100
... A45: 38 | B45: 111625201038 | C45: DINESH N | D45: M | E45: H | F45: M | H45: 50 | I45: 60 | J45: 57 | K45: 33 | L45: 70 | M45: =sum(H45:L45)/5 -> 54 | N45: =((COUNTIF((H45:L45),"<50"))+(COUNTIF((H45:L45),"=A"))) -> 1 | Q45: 100
A46: 39 | B46: 111625201039 | C46: DIVYA DHARSHINI C | D46: G | E46: D | F46: F | H46: 97 | I46: A | J46: 90 | K46: 57 | L46: 60 | M46: =sum(H46:L46)/5 -> 60.8 | N46: =((COUNTIF((H46:L46),"<50"))+(COUNTIF((H46:L46),"=A"))) -> 1 | Q46: 91
A47: 40 | B47: 111625201040 | C47: DIVYA T | D47: G | E47: H | F47: F | H47: 90 | I47: 90 | J47: 53 | K47: 84 | L47: 97 | M47: =sum(H47:L47)/5 -> 82.8 | N47: =((COUNTIF((H47:L47),"<50"))+(COUNTIF((H47:L47),"=A"))) -> 0 | Q47: 100
A48: 41 | B48: 111625201041 | C48: DONDETI BHARATH KUMAR REDDY | D48: M | E48: H | F48: M | H48: 33 | I48: 53.333333 | J48: 50 | K48: 27 | L48: 80 | M48: =sum(H48:L48)/5 -> 48.666667 | N48: =((COUNTIF((H48:L48),"<50"))+(COUNTIF((H48:L48),"=A"))) -> 2 | Q48: 100
A49: 42 | B49: 111625201042 | C49: DONDETI REVANTH REDDY | D49: M | E49: H | F49: M | H49: 60 | I49: 66.666667 | J49: 53 | K49: 9 | L49: 83 | M49: =sum(H49:L49)/5 -> 54.333333 | N49: =((COUNTIF((H49:L49),"<50"))+(COUNTIF((H49:L49),"=A"))) -> 1 | O49: =IF((N49<1),"0","1") -> 1 | P49: =COUNTIF((H49:L49),"=A") -> 0 | Q49: 100
A50: 43 | B50: 111625201043 | C50: DUVVURU DEEKSHITHA | D50: M | E50: H | F50: F | H50: 73 | I50: 83.333333 | J50: 53 | K50: 52 | L50: 80 | M50: =sum(H50:L50)/5 -> 68.266667 | N50: =((COUNTIF((H50:L50),"<50"))+(COUNTIF((H50:L50),"=A"))) -> 0 | O50: =IF((N50<1),"0","1") -> 0 | P50: =COUNTIF((H50:L50),"=A") -> 0 | Q50: 98
A51: 44 | B51: 111625201044 | C51: GANESH PRASATH J | D51: M | E51: D | F51: M | H51: 13 | I51: 33.333333 | J51: A | K51: 50 | L51: 63 | M51: =sum(H51:L51)/5 -> 31.866667 | N51: =((COUNTIF((H51:L51),"<50"))+(COUNTIF((H51:L51),"=A"))) -> 3 | O51: =IF((N51<1),"0","1") -> 1 | P51: =COUNTIF((H51:L51),"=A") -> 1 | Q51: 87
...

Sheet AIDS B
A1: R. M. K. COLLEGE OF ENGINEERING AND TECHNOLOGY
A2: R. S. M NAGAR, PUDUVOYAL - 601 206
A3: Department of Science and Humanities
A4: I Semester B.E (Academic Year : 2025-26)
A5: Unit Test - II Result Analysis
A6: Branch & Section: AIDS - B
A7: Sl. No. | B7: Reg. No. | C7: Name | D7: G / M | E7: D/H | F7: Girl / Boy | G7: Cut off | H7: Maths | I7: Chem | J7: C++ | K7: SDP | L7: DPSD | M7: GPA | N7: No. of subjects failed | P7: absentees | Q7: Attendance
A8: 1 | B8: 111625201063 | C8: JANANI B | D8: G | E8: D | F8: F | H8: 98 | I8: 77 | J8: 96 | K8: 83.333333 | L8: 83 | M8: =sum(H8:L8)/5 -> 87.466667 | N8: =((COUNTIF((H8:L8),"<50"))+(COUNTIF((H8:L8),"=A"))) -> 0 | O8: =IF((N8<1),"0","1") -> 0 | P8: =COUNTIF((H8:L8),"=A") -> 0 | Q8: 98
A9: 2 | B9: 111625201064 | C9: JANANI S | D9: M | E9: D | F9: F | H9: 81 | I9: 60 | J9: 63 | K9: A | L9: 63 | M9: =sum(H9:L9)/5 -> 53.4 | N9: =((COUNTIF((H9:L9),"<50"))+(COUNTIF((H9:L9),"=A"))) -> 1 | O9: =IF((N9<1),"0","1") -> 1 | P9: =COUNTIF((H9:L9),"=A") -> 1 | Q9: 94
A10: 3 | B10: 111625201065 | C10: JEEVARATHINAM M | D10: M | E10: D | F10: M | H10: 50 | I10: 80 | J10: 36 | K10: 60 | L10: 73 | M10: =sum(H10:L10)/5 -> 59.8 | N10: =((COUNTIF((H10:L10),"<50"))+(COUNTIF((H10:L10),"=A"))) -> 1 | O10: =IF((N10<1),"0","1") -> 1 | P10: =COUNTIF((H10:L10),"=A") -> 0 | Q10: 98
A11: 4 | B11: 111625201066 | C11: JEFFRIN M | D11: G | E11: H | F11: F | H11: 74 | I11: 90 | J11: 86 | K11: 90 | L11: 83 | M11: =sum(H11:L11)/5 -> 84.6 | N11: =((COUNTIF((H11:L11),"<50"))+(COUNTIF((H11:L11),"=A"))) -> 0 | O11: =IF((N11<1),"0","1") -> 0 | P11: =COUNTIF((H11:L11),"=A") -> 0 | Q11: 100
A12: 5 | B12: 111625201067 | C12: JERRIPOTHU VENKATA SAI KRISHNA | D12: M | E12: H | F12: M | H12: 60 | I12: 73 | J12: 50 | K12: 26.666667 | L12: 43 | M12: =sum(H12:L12)/5 -> 50.533333 | N12: =((COUNTIF((H12:L12),"<50"))+(COUNTIF((H12:L12),"=A"))) -> 2 | O12: =IF((N12<1),"0","1") -> 1 | P12: =COUNTIF((H12:L12),"=A") -> 0 | Q12: 100
A13: 6 | B13: 111625201068 | C13: JYOSHITHA N M | D13: M | E13: H | F13: F | H13: 12 | I13: 80 | J13: 23 | K13: 73.333333 | L13: 50 | M13: =sum(H13:L13)/5 -> 47.666667 | N13: =((COUNTIF((H13:L13),"<50"))+(COUNTIF((H13:L13),"=A"))) -> 2 | O13: =IF((N13<1),"0","1") -> 1 | P13: =COUNTIF((H13:L13),"=A") -> 0 | Q13: 100
A14: 7 | B14: 111625201069 | C14: KAILASH S | D14: M | E14: D | F14: M | H14: 50 | I14: 50 | J14: 66 | K14: 60 | L14: 50 | M14: =sum(H14:L14)/5 -> 55.2 | N14: =((COUNTIF((H14:L14),"<50"))+(COUNTIF((H14:L14),"=A"))) -> 0 | O14: =IF((N14<1),"0","1") -> 0 | P14: =COUNTIF((H14:L14),"=A") -> 0 | Q14: 96
A15: 8 | B15: 111625201070 | C15: KAMALESH S | D15: G | E15: D | F15: M | H15: 50 | I15: 53 | J15: 67 | K15: 16.666667 | L15: 50 | M15: =sum(H15:L15)/5 -> 47.333333 | N15: =((COUNTIF((H15:L15),"<50"))+(COUNTIF((H15:L15),"=A"))) -> 1 | O15: =IF((N15<1),"0","1") -> 1 | P15: =COUNTIF((H15:L15),"=A") -> 0 | Q15: 100
A16: 9 | B16: 111625201071 | C16: KAMESH H | D16: M | E16: H | F16: M | H16: 50 | I16: 63 | J16: 37 | K16: 50 | L16: 50 | M16: =sum(H16:L16)/5 -> 50 | N16: =((COUNTIF((H16:L16),"<50"))+(COUNTIF((H16:L16),"=A"))) -> 1 | O16: =IF((N16<1),"0","1") -> 1 | P16: =COUNTIF((H16:L16),"=A") -> 0 | Q16: 100
A17: 10 | B17: 111625201072 | C17: KANCHARALA VENKATA MOHAN REDDDY | D17: M | E17: H | F17: M | H17: 52 | I17: 50 | J17: 19 | K17: 36.666667 | L17: 50 | M17: =sum(H17:L17)/5 -> 41.533333 | N17: =((COUNTIF((H17:L17),"<50"))+(COUNTIF((H17:L17),"=A"))) -> 2 | O17: =IF((N17<1),"0","1") -> 1 | P17: =COUNTIF((H17:L17),"=A") -> 0 | Q17: 98
A18: 11 | B18: 111625201073 | C18: KANESKA S M | D18: G | E18: H | F18: F | H18: 51 | I18: 53 | J18: 3 | K18: 50 | L18: 50 | M18: =sum(H18:L18)/5 -> 41.4 | N18: =((COUNTIF((H18:L18),"<50"))+(COUNTIF((H18:L18),"=A"))) -> 1 | O18: =IF((N18<1),"0","1") -> 1 | P18: =COUNTIF((H18:L18),"=A") -> 0 | Q18: 94
A19: 12 | B19: 111625201074 | C19: KANI MOZHI R | D19: G | E19: H | F19: F | H19: 53 | I19: 87 | J19: 96 | K19: 83.333333 | L19: 77 | M19: =sum(H19:L19)/5 -> 79.266667 | N19: =((COUNTIF((H19:L19),"<50"))+(COUNTIF((H19:L19),"=A"))) -> 0 | O19: =IF((N19<1),"0","1") -> 0 | P19: =COUNTIF((H19:L19),"=A") -> 0 | Q19: 100
A20: 13 | B20: 111625201075 | C20: KASU RAKESH REDDY | D20: M | E20: H | F20: M | H20: 54 | I20: 27 | J20: 16 | K20: 20 | L20: 3 | M20: =sum(H20:L20)/5 -> 24 | N20: =((COUNTIF((H20:L20),"<50"))+(COUNTIF((H20:L20),"=A"))) -> 4 | O20: =IF((N20<1),"0","1") -> 1 | P20: =COUNTIF((H20:L20),"=A") -> 0 | Q20: 98
A21: 14 | B21: 111625201076 | C21: KAVIARASI D | D21: G | E21: D | F21: F | H21: 50 | I21: 50 | J21: 13 | K21: 66.666667 | L21: 50 | M21: =sum(H21:L21)/5 -> 45.933333 | N21: =((COUNTIF((H21:L21),"<50"))+(COUNTIF((H21:L21),"=A"))) -> 1 | O21: =IF((N21<1),"0","1") -> 1 | P21: =COUNTIF((H21:L21),"=A") -> 0 | Q21: 98
A22: 15 | B22: 111625201077 | C22: KAVIYA SRI V | D22: G | E22: D | F22: F | H22: 88 | I22: 83 | J22: 83 | K22: 86.666667 | L22: 100 | M22: =sum(H22:L22)/5 -> 88.133333 | N22: =((COUNTIF((H22:L22),"<50"))+(COUNTIF((H22:L22),"=A"))) -> 0 | O22: =IF((N22<1),"0","1") -> 0 | P22: =COUNTIF((H22:L22),"=A") -> 0 | Q22: 100
A23: 16 | B23: 111625201078 | C23: KESAVARAJ S | D23: G | E23: H | F23: M | H23: 56 | I23: 63 | J23: 80 | K23: 76.666667 | L23: 50 | M23: =sum(H23:L23)/5 -> 65.133333 | N23: =((COUNTIF((H23:L23),"<50"))+(COUNTIF((H23:L23),"=A"))) -> 0 | Q23: 100
A24: 17 | B24: 111625201079 | C24: KETHU BHUVANESWARI | D24: M | E24: H | F24: F | H24: 74 | I24: 57 | J24: 50 | K24: 60 | L24: 73 | M24: =sum(H24:L24)/5 -> 62.8 | N24: =((COUNTIF((H24:L24),"<50"))+(COUNTIF((H24:L24),"=A"))) -> 0 | Q24: 100
A25: 18 | B25: 111625201080 | C25: KETHU JYOTHISWAR REDDY | D25: M | E25: H | F25: M | H25: 95 | I25: 90 | J25: 87 | K25: 75 | L25: 53 | M25: =sum(H25:L25)/5 -> 80 | N25: =((COUNTIF((H25:L25),"<50"))+(COUNTIF((H25:L25),"=A"))) -> 0 | Q25: 94
A26: 19 | B26: 111625201081 | C26: KOLAMALA JAHNAVI | D26: M | E26: H | F26: F | H26: 100 | I26: 83 | J26: 63 | K26: 83.333333 | L26: 97 | M26: =sum(H26:L26)/5 -> 85.266667 | N26: =((COUNTIF((H26:L26),"<50"))+(COUNTIF((H26:L26),"=A"))) -> 0 | Q26: 100
A27: 20 | B27: 111625201082 | C27: KOMMI SAI VARNIKA | D27: M | E27: H | F27: F | H27: 52 | I27: 77 | J27: 26 | K27: 26.666667 | L27: 97 | M27: =sum(H27:L27)/5 -> 55.733333 | N27: =((COUNTIF((H27:L27),"<50"))+(COUNTIF((H27:L27),"=A"))) -> 2 | Q27: 100
A28: 21 | B28: 111625201083 | C28: KONDURU SUSMITHA | D28: M | E28: H | F28: F | H28: 50 | I28: 63 | J28: 50 | K28: 80 | L28: 60 | M28: =sum(H28:L28)/5 -> 60.6 | N28: =((COUNTIF((H28:L28),"<50"))+(COUNTIF((H28:L28),"=A"))) -> 0 | Q28: 100
A29: 22 | B29: 111625201084 | C29: KOTA SAI CHARAN | D29: M | E29: H | F29: M | H29: 11 | I29: 50 | J29: 0 | K29: 26.666667 | L29: 37 | M29: =sum(H29:L29)/5 -> 24.933333 | N29: =((COUNTIF((H29:L29),"<50"))+(COUNTIF((H29:L29),"=A"))) -> 4 | Q29: 100
A30: 23 | B30: 111625201085 | C30: KRISHKA M | D30: G | E30: D | F30: F | H30: 53 | I30: 80 | J30: 76 | K30: 53.333333 | L30: 77 | M30: =sum(H30:L30)/5 -> 67.866667 | N30: =((COUNTIF((H30:L30),"<50"))+(COUNTIF((H30:L30),"=A"))) -> 0 | Q30: 98
A31: 24 | B31: 111625201086 | C31: LAKSHANIKA S T K | D31: M | E31: D | F31: F | H31: 74 | I31: 77 | J31: 100 | K31: 83.333333 | L31: 97 | M31: =sum(H31:L31)/5 -> 86.266667 | N31: =((COUNTIF((H31:L31),"<50"))+(COUNTIF((H31:L31),"=A"))) -> 0 | Q31: 96
A32: 25 | B32: 111625201087 | C32: LAKSHMI NARAYANAN S B | D32: M | E32: D | F32: M | H32: 60 | I32: 53 | J32: 50 | K32: 26.666667 | L32: 50 | M32: =sum(H32:L32)/5 -> 47.933333 | N32: =((COUNTIF((H32:L32),"<50"))+(COUNTIF((H32:L32),"=A"))) -> 1 | Q32: 98
A33: 26 | B33: 111625201088 | C33: LEKHA G | D33: G | E33: D | F33: F | H33: 77 | I33: 87 | J33: 96 | K33: 76.666667 | L33: 100 | M33: =sum(H33:L33)/5 -> 87.333333 | N33: =((COUNTIF((H33:L33),"<50"))+(COUNTIF((H33:L33),"=A"))) -> 0 | Q33: 98
A34: 27 | B34: 111625201089 | C34: LEKKALA PRANATHI | D34: M | E34: H | F34: F | H34: 74 | I34: 77 | J34: 73 | K34: 90 | L34: 67 | M34: =sum(H34:L34)/5 -> 76.2 | N34: =((COUNTIF((H34:L34),"<50"))+(COUNTIF((H34:L34),"=A"))) -> 0 | Q34: 100
... A39: 32 | B39: 111625201094 | C39: MADHAN KUMAR | D39: G | E39: H | F39: M | H39: 88 | I39: 83 | J39: 90 | K39: 80 | L39: 80 | M39: =sum(H39:L39)/5 -> 84.2 | N39: =((COUNTIF((H39:L39),"<50"))+(COUNTIF((H39:L39),"=A"))) -> 0 | Q39: 100
A40: 33 | B40: 111625201095 | C40: MANOJ SAMUEL S | D40: M | E40: D | F40: M | H40: 28 | I40: 60 | J40: A | K40: 26.666667 | L40: 23 | M40: =sum(H40:L40)/5 -> 27.533333 | N40: =((COUNTIF((H40:L40),"<50"))+(COUNTIF((H40:L40),"=A"))) -> 4 | Q40: 83
A41: 34 | B41: 111625201096 | C41: MELLAKANTI RUCHITHA | D41: M | E41: H | F41: F | H41: 50 | I41: 63 | J41: 30 | K41: 20 | L41: 27 | M41: =sum(H41:L41)/5 -> 38 | N41: =((COUNTIF((H41:L41),"<50"))+(COUNTIF((H41:L41),"=A"))) -> 3 | Q41: 94
A42: 35 | B42: 111625201097 | C42: MOHAMED IRFAN I | D42: G | E42: D | F42: M | H42: 60 | I42: 63 | J42: 53 | K42: 56.666667 | L42: 60 | M42: =sum(H42:L42)/5 -> 58.533333 | N42: =((COUNTIF((H42:L42),"<50"))+(COUNTIF((H42:L42),"=A"))) -> 0 | Q42: 98
A43: 36 | B43: 111625201098 | C43: MONISHA S | D43: G | E43: D | F43: F | H43: 77 | I43: 83 | J43: 96 | K43: 76.666667 | L43: 50 | M43: =sum(H43:L43)/5 -> 76.533333 | N43: =((COUNTIF((H43:L43),"<50"))+(COUNTIF((H43:L43),"=A"))) -> 0 | Q43: 94
A44: 37 | B44: 111625201099 | C44: MUKESH S | D44: G | E44: D | F44: M | H44: 51 | I44: 53 | J44: 50 | K44: 66.666667 | L44: A | M44: =sum(H44:L44)/5 -> 44.133333 | N44: =((COUNTIF((H44:L44),"<50"))+(COUNTIF((H44:L44),"=A"))) -> 1 | O44: =IF((N44<1),"0","1") -> 1 | P44: =COUNTIF((H44:L44),"=A") -> 1 | Q44: 89
...

Sheet AIDS C
A1: R. M. K. COLLEGE OF ENGINEERING AND TECHNOLOGY
A2: R. S. M NAGAR, PUDUVOYAL - 601 206
A3: Department of Science and Humanities
A4: I Semester B.E (Academic Year : 2025-26)
A5: Unit Test - II Result Analysis
A6: Branch & Section: AIDS - C
A7: Sl. No. | B7: Reg. No. | C7: Name | D7: G / M | E7: D/H | F7: Girl / Boy | G7: Cut off | H7: Maths | I7: Chem | J7: C++ | K7: SDP | L7: DPSD | M7: GPA | N7: No. of subjects failed | P7: absentees | Q7: Attendance
A8: 1 | B8: 111625201125 | C8: RADARAPU BABY JANANI | D8: M | E8: H | F8: F | H8: 97 | I8: 76.666667 | J8: 77 | K8: 50 | L8: 83 | M8: =sum(H8:L8)/5 -> 76.733333 | N8: =((COUNTIF((H8:L8),"<50"))+(COUNTIF((H8:L8),"=A"))) -> 0 | O8: =IF((N8<1),"0","1") -> 0 | P8: =COUNTIF((H8:L8),"=A") -> 0 | Q8: 100
A9: 2 | B9: 111625201126 | C9: RAHUL K | D9: M | E9: H | F9: M | H9: 20 | I9: 50 | J9: 74 | K9: 27 | L9: 30 | M9: =sum(H9:L9)/5 -> 40.2 | N9: =((COUNTIF((H9:L9),"<50"))+(COUNTIF((H9:L9),"=A"))) -> 3 | O9: =IF((N9<1),"0","1") -> 1 | P9: =COUNTIF((H9:L9),"=A") -> 0 | Q9: 98
A10: 3 | B10: 111625201127 | C10: RAJASRI G | D10: G | E10: D | F10: F | H10: 70 | I10: 60 | J10: 63 | K10: 27 | L10: 93 | M10: =sum(H10:L10)/5 -> 62.6 | N10: =((COUNTIF((H10:L10),"<50"))+(COUNTIF((H10:L10),"=A"))) -> 1 | O10: =IF((N10<1),"0","1") -> 1 | P10: =COUNTIF((H10:L10),"=A") -> 0 | Q10: 94
A11: 4 | B11: 111625201128 | C11: RAMACHANDRAN G | D11: G | E11: H | F11: M | H11: 77 | I11: 76.666667 | J11: 50 | K11: 70 | L11: 57 | M11: =sum(H11:L11)/5 -> 66.133333 | N11: =((COUNTIF((H11:L11),"<50"))+(COUNTIF((H11:L11),"=A"))) -> 0 | O11: =IF((N11<1),"0","1") -> 0 | P11: =COUNTIF((H11:L11),"=A") -> 0 | Q11: 100
A12: 5 | B12: 111625201129 | C12: RAMISETTY LASYA BHAVANI | D12: M | E12: H | F12: F | H12: 30 | I12: 50 | J12: 27 | K12: 17 | L12: 63 | M12: =sum(H12:L12)/5 -> 37.4 | N12: =((COUNTIF((H12:L12),"<50"))+(COUNTIF((H12:L12),"=A"))) -> 3 | O12: =IF((N12<1),"0","1") -> 1 | P12: =COUNTIF((H12:L12),"=A") -> 0 | Q12: 100
A13: 6 | B13: 111625201130 | C13: RANJITH N B | D13: G | E13: H | F13: M | H13: 73 | I13: 66.666667 | J13: 87 | K13: 87 | L13: 70 | M13: =sum(H13:L13)/5 -> 76.733333 | N13: =((COUNTIF((H13:L13),"<50"))+(COUNTIF((H13:L13),"=A"))) -> 0 | O13: =IF((N13<1),"0","1") -> 0 | P13: =COUNTIF((H13:L13),"=A") -> 0 | Q13: 100
A14: 7 | B14: 111625201131 | C14: RITHIKA J | D14: G | E14: H | F14: F | H14: 73 | I14: 80 | J14: 83 | K14: 77 | L14: 93 | M14: =sum(H14:L14)/5 -> 81.2 | N14: =((COUNTIF((H14:L14),"<50"))+(COUNTIF((H14:L14),"=A"))) -> 0 | O14: =IF((N14<1),"0","1") -> 0 | P14: =COUNTIF((H14:L14),"=A") -> 0 | Q14: 100
A15: 8 | B15: 111625201132 | C15: RITU N | D15: G | E15: D | F15: F | H15: 50 | I15: 63.333333 | J15: 67 | K15: 53 | L15: 67 | M15: =sum(H15:L15)/5 -> 60.066667 | N15: =((COUNTIF((H15:L15),"<50"))+(COUNTIF((H15:L15),"=A"))) -> 0 | O15: =IF((N15<1),"0","1") -> 0 | P15: =COUNTIF((H15:L15),"=A") -> 0 | Q15: 96
A16: 9 | B16: 111625201133 | C16: RUVANTHIKA S T K | D16: M | E16: D | F16: F | H16: 80 | I16: 83.333333 | J16: 53 | K16: A | L16: 80 | M16: =sum(H16:L16)/5 -> 59.266667 | N16: =((COUNTIF((H16:L16),"<50"))+(COUNTIF((H16:L16),"=A"))) -> 1 | O16: =IF((N16<1),"0","1") -> 1 | P16: =COUNTIF((H16:L16),"=A") -> 1 | Q16: 94
A17: 10 | B17: 111625201134 | C17: SACHIN D | D17: G | E17: D | F17: M | H17: 70 | I17: 63.333333 | J17: 70 | K17: A | L17: 50 | M17: =sum(H17:L17)/5 -> 50.666667 | N17: =((COUNTIF((H17:L17),"<50"))+(COUNTIF((H17:L17),"=A"))) -> 1 | Q17: 53
A18: 11 | B18: 111625201135 | C18: SAISHREYASH K S | D18: M | E18: D | F18: M | H18: 57 | I18: 66.666667 | J18: 77 | K18: 60 | L18: 70 | M18: =sum(H18:L18)/5 -> 66.133333 | N18: =((COUNTIF((H18:L18),"<50"))+(COUNTIF((H18:L18),"=A"))) -> 0 | Q18: 100
A19: 12 | B19: 111625201136 | C19: SAM ELIJAH BG | D19: M | E19: D | F19: M | H19: 87 | I19: 53.333333 | J19: 63 | K19: 50 | L19: 30 | M19: =sum(H19:L19)/5 -> 56.666667 | N19: =((COUNTIF((H19:L19),"<50"))+(COUNTIF((H19:L19),"=A"))) -> 1 | Q19: 98
A20: 13 | B20: 111625201137 | C20: SAM NICHOLAS H | D20: M | E20: D | F20: M | H20: 20 | I20: 63.333333 | J20: 50 | K20: 50 | L20: 57 | M20: =sum(H20:L20)/5 -> 48.066667 | N20: =((COUNTIF((H20:L20),"<50"))+(COUNTIF((H20:L20),"=A"))) -> 1 | Q20: 91
A21: 14 | B21: 111625201138 | C21: SANCHITA V | D21: G | E21: D | F21: F | H21: 100 | I21: 86.666667 | J21: 70 | K21: 57 | L21: 70 | M21: =sum(H21:L21)/5 -> 76.733333 | N21: =((COUNTIF((H21:L21),"<50"))+(COUNTIF((H21:L21),"=A"))) -> 0 | Q21: 87
A22: 15 | B22: 111625201139 | C22: SANDHIYA B | D22: G | E22: H | F22: F | H22: 97 | I22: 80 | J22: 57 | K22: 50 | L22: 87 | M22: =sum(H22:L22)/5 -> 74.2 | N22: =((COUNTIF((H22:L22),"<50"))+(COUNTIF((H22:L22),"=A"))) -> 0 | Q22: 96
A23: 16 | B23: 111625201140 | C23: SANDHIYA V | D23: G | E23: H | F23: F | H23: 77 | I23: 63.333333 | J23: 60 | K23: 50 | L23: 70 | M23: =sum(H23:L23)/5 -> 64.066667 | N23: =((COUNTIF((H23:L23),"<50"))+(COUNTIF((H23:L23),"=A"))) -> 0 | Q23: 100
A24: 17 | B24: 111625201141 | C24: SANGEETHA SRI R | D24: G | E24: D | F24: F | H24: 60 | I24: 80 | J24: 77 | K24: 57 | L24: 70 | M24: =sum(H24:L24)/5 -> 68.8 | N24: =((COUNTIF((H24:L24),"<50"))+(COUNTIF((H24:L24),"=A"))) -> 0 | Q24: 96
A25: 18 | B25: 111625201142 | C25: SANJANA N | D25: G | E25: D | F25: F | H25: 93 | I25: 90 | J25: 67 | K25: 73 | L25: 50 | M25: =sum(H25:L25)/5 -> 74.6 | N25: =((COUNTIF((H25:L25),"<50"))+(COUNTIF((H25:L25),"=A"))) -> 0 | Q25: 94
A26: 19 | B26: 111625201143 | C26: SANJAY SRIDHAR D A | D26: G | E26: H | F26: M | H26: 60 | I26: 73.333333 | J26: 63 | K26: 51 | L26: 70 | M26: =sum(H26:L26)/5 -> 63.466667 | N26: =((COUNTIF((H26:L26),"<50"))+(COUNTIF((H26:L26),"=A"))) -> 0 | Q26: 98
A27: 20 | B27: 111625201144 | C27: SANJU SHREE G | D27: G | E27: D | F27: F | H27: 73 | I27: 83.333333 | J27: 87 | K27: 50 | L27: 87 | M27: =sum(H27:L27)/5 -> 76.066667 | N27: =((COUNTIF((H27:L27),"<50"))+(COUNTIF((H27:L27),"=A"))) -> 0 | Q27: 96
A28: 21 | B28: 111625201145 | C28: SANTHOSH P | D28: G | E28: D | F28: M | H28: 80 | I28: 60 | J28: 90 | K28: 33 | L28: 63 | M28: =sum(H28:L28)/5 -> 65.2 | N28: =((COUNTIF((H28:L28),"<50"))+(COUNTIF((H28:L28),"=A"))) -> 1 | Q28: 94
A29: 22 | B29: 111625201146 | C29: SARAVANAN B L | D29: G | E29: D | F29: M | H29: 63 | I29: 76.666667 | J29: 37 | K29: 53 | L29: 13 | M29: =sum(H29:L29)/5 -> 48.533333 | N29: =((COUNTIF((H29:L29),"<50"))+(COUNTIF((H29:L29),"=A"))) -> 2 | Q29: 98
... A31: 24 | B31: 111625201148 | C31: SHAMREEN FATHIMA J | D31: G | E31: D | F31: F | H31: 97 | I31: 83.333333 | J31: 90 | K31: 80 | L31: 83 | M31: =sum(H31:L31)/5 -> 86.666667 | N31: =((COUNTIF((H31:L31),"<50"))+(COUNTIF((H31:L31),"=A"))) -> 0 | Q31: 96
A32: 25 | B32: 111625201149 | C32: SHEETHAL S | D32: G | E32: D | F32: F | H32: A | I32: A | J32: A | K32: A | L32: A | M32: =sum(H32:L32)/5 -> 0 | N32: =((COUNTIF((H32:L32),"<50"))+(COUNTIF((H32:L32),"=A"))) -> 5 | Q32: 87
A33: 26 | B33: 111625201150 | C33: SHIVANI M | D33: G | E33: D | F33: F | H33: 87 | I33: 73.333333 | J33: 90 | K33: 73 | L33: 97 | M33: =sum(H33:L33)/5 -> 84.066667 | N33: =((COUNTIF((H33:L33),"<50"))+(COUNTIF((H33:L33),"=A"))) -> 0 | Q33: 100
A34: 27 | B34: 111625201151 | C34: SHREE DHARSHAN B R | D34: M | E34: D | F34: M | H34: 80 | I34: 66.666667 | J34: 87 | K34: 57 | L34: 13 | M34: =sum(H34:L34)/5 -> 60.733333 | N34: =((COUNTIF((H34:L34),"<50"))+(COUNTIF((H34:L34),"=A"))) -> 1 | Q34: 98
A35: 28 | B35: 111625201152 | C35: SIVARUBAN K G | D35: M | E35: H | F35: M | H35: 50 | I35: 30 | J35: 70 | K35: 37 | L35: 50 | M35: =sum(H35:L35)/5 -> 47.4 | N35: =((COUNTIF((H35:L35),"<50"))+(COUNTIF((H35:L35),"=A"))) -> 2 | Q35: 96
A36: 29 | B36: 111625201153 | C36: SOLLETI ANVITHA | D36: M | E36: H | F36: F | H36: 90 | I36: 56.666667 | J36: 67 | K36: 53 | L36: 57 | M36: =sum(H36:L36)/5 -> 64.733333 | N36: =((COUNTIF((H36:L36),"<50"))+(COUNTIF((H36:L36),"=A"))) -> 0 | Q36: 100
A37: 30 | B37: 111625201154 | C37: SUBHASHINI K | D37: G | E37: D | F37: F | H37: 90 | I37: 90 | J37: 93 | K37: 83 | L37: 63 | M37: =sum(H37:L37)/5 -> 83.8 | N37: =((COUNTIF((H37:L37),"<50"))+(COUNTIF((H37:L37),"=A"))) -> 0 | Q37: 98
A38: 31 | B38: 111625201155 | C38: SUMANTH S | D38: G | E38: D | F38: M | H38: 77 | I38: 66.666667 | J38: 83 | K38: 57 | L38: 50 | M38: =sum(H38:L38)/5 -> 66.733333 | N38: =((COUNTIF((H38:L38),"<50"))+(COUNTIF((H38:L38),"=A"))) -> 0 | O38: =IF((N38<1),"0","1") -> 0 | P38: =COUNTIF((H38:L38),"=A") -> 0 | Q38: 100
A39: 32 | B39: 111625201156 | C39: SURENDHAR K | D39: G | E39: D | F39: M | H39: 50 | I39: 73 | J39: 43 | K39: 13 | L39: 50 | M39: =sum(H39:L39)/5 -> 45.8 | N39: =((COUNTIF((H39:L39),"<50"))+(COUNTIF((H39:L39),"=A"))) -> 2 | O39: =IF((N39<1),"0","1") -> 1 | P39: =COUNTIF((H39:L39),"=A") -> 0 | Q39: 100
A40: 33 | B40: 111625201157 | C40: SYED AHMED BASHA | D40: M | E40: H | F40: M | H40: 50 | I40: 50 | J40: 17 | K40: 33 | L40: 63 | M40: =sum(H40:L40)/5 -> 42.6 | N40: =((COUNTIF((H40:L40),"<50"))+(COUNTIF((H40:L40),"=A"))) -> 2 | O40: =IF((N40<1),"0","1") -> 1 | P40: =COUNTIF((H40:L40),"=A") -> 0 | Q40: 89
A41: 34 | B41: 111625201158 | C41: TEJA SAI C | D41: G | E41: D | F41: M | H41: 93 | I41: 90 | J41: 83 | K41: 77 | L41: 70 | M41: =sum(H41:L41)/5 -> 82.6 | N41: =((COUNTIF((H41:L41),"<50"))+(COUNTIF((H41:L41),"=A"))) -> 0 | O41: =IF((N41<1),"0","1") -> 0 | P41: =COUNTIF((H41:L41),"=A") -> 0 | Q41: 100
...

Sheet Overall
A1: R.M.K.COLLEGE OF ENGINEERING AND TECHNOLOGY
A3: R.S.M. NAGAR, PUDUVOYAL - 601 206
A5: Batch: 17 Date: 4.10.24
A7: I Semester B.E (Academic Year : 2025-26)
A8: IAT1 Result Analysis
C12: Dept. | D12: STUDENTS APPEARED | E12: STUDENTS PASSED | F12: STUDENTS FAILED | G12: PASS %
C14: AIDS | D14: =(COUNT('AIDS A'!A8:A69)+COUNT('AIDS B'!A8:A69)+COUNT('AIDS C'!A8:A69)) -> 186 | E14: =D14-F14 -> 94 | F14: ='AIDS A'!H80+'AIDS B'!H80+'AIDS C'!H79 -> 92 | G14: =(E14/D14)*100 -> 50.537634
B16: No. of Failures(Dept.wise)
B17: Dept. | C17: Maths | D17: Chem | E17: C++ | F17: SDP | G17: DPSD | H17: Total
B18: AIDS | C18: ='AIDS A'!H75+'AIDS B'!H75+'AIDS A'!H73+'AIDS B'!H73+'AIDS C'!H74+'AIDS C'!H72 -> 24 | D18: ='AIDS A'!I75+'AIDS B'!I75+'AIDS A'!I73+'AIDS B'!I73+'AIDS C'!I74+'AIDS C'!I72 -> 24 | E18: ='AIDS A'!J75+'AIDS B'!J75+'AIDS A'!J73+'AIDS B'!J73+'AIDS C'!J74+'AIDS C'!J72 -> 42 | F18: ='AIDS A'!K75+'AIDS B'!K75+'AIDS A'!K73+'AIDS B'!K73+'AIDS C'!K74+'AIDS C'!K72 -> 63 | G18: ='AIDS A'!L75+'AIDS B'!L75+'AIDS A'!L73+'AIDS B'!L73+'AIDS C'!L74+'AIDS C'!L72 -> 27 | H18: =sum(C18:G18) -> 180
B19: Failed only in | C19: ='AIDS A'!H77+'AIDS B'!H77+'AIDS C'!H76 -> 4 | D19: ='AIDS A'!I77+'AIDS B'!I77+'AIDS C'!I76 -> 3 | E19: ='AIDS A'!J77+'AIDS B'!J77+'AIDS C'!J76 -> 6 | F19: ='AIDS A'!K77+'AIDS B'!K77+'AIDS C'!K76 -> 20 | G19: ='AIDS A'!L77+'AIDS B'!L77+'AIDS C'!L76 -> 6 | H19: =sum(C19:G19) -> 39
B22: Dept. | C22: One Sub. failures | D22: Two Sub. failures | E22: Three Sub. failures | F22: Four Sub. failures | G22: Five Sub. failures | H22: Total No. of subjects
B23: AIDS | C23: =(COUNTIF(('AIDS A'!N8:N69),"=1"))+(COUNTIF(('AIDS B'!N8:N69),"=1"))+(COUNTIF(('AIDS C'!N8:N69),"=1")) -> 39 | D23: =(COUNTIF(('AIDS A'!N8:N69),"=2"))+(COUNTIF(('AIDS B'!N8:N69),"=2"))+(COUNTIF(('AIDS C'!N8:N69),"=2")) -> 30 | E23: =(COUNTIF(('AIDS A'!N8:N69),"=3"))+(COUNTIF(('AIDS B'!N8:N69),"=3"))+(COUNTIF(('AIDS C'!N8:N69),"=3")) -> 13 | F23: =(COUNTIF(('AIDS A'!N8:N69),"=4"))+(COUNTIF(('AIDS B'!N8:N69),"=4"))+(COUNTIF(('AIDS C'!N8:N69),"=4")) -> 8 | G23: =(COUNTIF(('AIDS A'!N8:N69),"=5"))+(COUNTIF(('AIDS B'!N8:N69),"=5"))+(COUNTIF(('AIDS C'!N8:N69),"=5")) -> 2 | H23: =(C23*1)+(D23*2)+(E23*3)+(F23*4)+(G23*5) -> 180
