Workbook

Sheet AIDS A
A1: R. M. K. COLLEGE OF ENGINEERING AND TECHNOLOGY
A2: R. S. M NAGAR, PUDUVOYAL - 601 206
A3: Department of Science and Humanities
A4: I Semester B.E (Academic Year : 2025-26)
A5: Unit Test - II Result Analysis
A6: Branch & Section:AIDS - A
A7: Sl. No. | B7: Reg. No. | C7: Name | D7: Cut off | E7: Maths | F7: Chem | G7: C++ | H7: SDP | I7: DPSD | J7: GPA | K7: No. of subjects failed | M7: absentees | N7: Attendance
A8: 1 | B8: 111625201001 | C8: ABIJITH G S | E8: A | F8: A | G8: 63 | H8: 30 | I8: 80 | J8: =SUM(E8:I8)/5 -> 34.6 | K8: =((COUNTIF((E8:I8),"<50"))+(COUNTIF((E8:I8),"=A"))) -> 3 | L8: =IF((K8<1),"0","1") -> 1 | M8: =COUNTIF((E8:I8),"=A") -> 2 | N8: 91
A9: 2 | B9: 111625201002 | C9: ABISHEK M | E9: 67 | F9: 53.333333 | G9: 53 | H9: 60 | I9: 63 | J9: =SUM(E9:I9)/5 -> 59.266667 | K9: =((COUNTIF((E9:I9),"<50"))+(COUNTIF((E9:I9),"=A"))) -> 0 | L9: =IF((K9<1),"0","1") -> 0 | M9: =COUNTIF((E9:I9),"=A") -> 0 | N9: 100
A10: 3 | B10: 111625201003 | C10: ADDIPALLI LAHITH VARMA | E10: 50 | F10: 50 | G10: 20 | H10: 30 | I10: 13 | J10: =SUM(E10:I10)/5 -> 32.6 | K10: =((COUNTIF((E10:I10),"<50"))+(COUNTIF((E10:I10),"=A"))) -> 3 | L10: =IF((K10<1),"0","1") -> 1 | M10: =COUNTIF((E10:I10),"=A") -> 0 | N10: 100
A11: 4 | B11: 111625201004 | C11: AJAY R V | E11: 53 | F11: 73.333333 | G11: 63 | H11: 73 | I11: 67 | J11: =SUM(E11:I11)/5 -> 65.866667 | K11: =((COUNTIF((E11:I11),"<50"))+(COUNTIF((E11:I11),"=A"))) -> 0 | L11: =IF((K11<1),"0","1") -> 0 | M11: =COUNTIF((E11:I11),"=A") -> 0 | N11: 98
A12: 5 | B12: 111625201005 | C12: AKSHAYA K | E12: 67 | F12: 70 | G12: 80 | H12: 77 | I12: 80 | J12: =SUM(E12:I12)/5 -> 74.8 | K12: =((COUNTIF((E12:I12),"<50"))+(COUNTIF((E12:I12),"=A"))) -> 0 | L12: =IF((K12<1),"0","1") -> 0 | M12: =COUNTIF((E12:I12),"=A") -> 0 | N12: 98
A13: 6 | B13: 111625201006 | C13: AKSHAYA R | E13: 53 | F13: 93.333333 | G13: 77 | H13: 53 | I13: 90 | J13: =SUM(E13:I13)/5 -> 73.266667 | K13: =((COUNTIF((E13:I13),"<50"))+(COUNTIF((E13:I13),"=A"))) -> 0 | L13: =IF((K13<1),"0","1") -> 0 | M13: =COUNTIF((E13:I13),"=A") -> 0 | N13: 100
A14: 7 | B14: 111625201007 | C14: ANAGHA SRIRAM S | E14: 77 | F14: 50 | G14: 63 | H14: 30 | I14: 50 | J14: =SUM(E14:I14)/5 -> 54 | K14: =((COUNTIF((E14:I14),"<50"))+(COUNTIF((E14:I14),"=A"))) -> 1 | L14: =IF((K14<1),"0","1") -> 1 | M14: =COUNTIF((E14:I14),"=A") -> 0 | N14: 96
A15: 8 | B15: 111625201008 | C15: ANIPIREDDY LEELA VISHNU REDDY | E15: 50 | F15: 36.666667 | G15: 63 | H15: 17 | I15: 57 | J15: =SUM(E15:I15)/5 -> 44.733333 | K15: =((COUNTIF((E15:I15),"<50"))+(COUNTIF((E15:I15),"=A"))) -> 2 | L15: =IF((K15<1),"0","1") -> 1 | M15: =COUNTIF((E15:I15),"=A") -> 0 | N15: 96
A16: 9 | B16: 111625201009 | C16: ANISHA LAKSHMI G S | E16: 77 | F16: 86.666667 | G16: 67 | H16: 77 | I16: 93 | J16: =SUM(E16:I16)/5 -> 80.133333 | K16: =((COUNTIF((E16:I16),"<50"))+(COUNTIF((E16:I16),"=A"))) -> 0 | L16: =IF((K16<1),"0","1") -> 0 | M16: =COUNTIF((E16:I16),"=A") -> 0 | N16: 98
A17: 10 | B17: 111625201010 | C17: ARAVIND ALAGAPPAN AR | E17: 60 | F17: 66.666667 | G17: 67 | H17: 51 | I17: 87 | J17: =SUM(E17:I17)/5 -> 66.333333 | K17: =((COUNTIF((E17:I17),"<50"))+(COUNTIF((E17:I17),"=A"))) -> 0 | L17: =IF((K17<1),"0","1") -> 0 | M17: =COUNTIF((E17:I17),"=A") -> 0 | N17: 96
A18: 11 | B18: 111625201011 | C18: ARCHANA ANBAZHAGAN | E18: 80 | F18: 70 | G18: 20 | H18: 60 | I18: 43 | J18: =SUM(E18:I18)/5 -> 54.6 | K18: =((COUNTIF((E18:I18),"<50"))+(COUNTIF((E18:I18),"=A"))) -> 2 | L18: =IF((K18<1),"0","1") -> 1 | M18: =COUNTIF((E18:I18),"=A") -> 0 | N18: 96
A19: 12 | B19: 111625201012 | C19: AREDDULA VARSHITH KUMAR | E19: 60 | F19: 50 | G19: 50 | H19: 30 | I19: 50 | J19: =SUM(E19:I19)/5 -> 48 | K19: =((COUNTIF((E19:I19),"<50"))+(COUNTIF((E19:I19),"=A"))) -> 1 | L19: =IF((K19<1),"0","1") -> 1 | M19: =COUNTIF((E19:I19),"=A") -> 0 | N19: 96
A20: 13 | B20: 111625201013 | C20: ARIGELA LIKITH SRINIVAS | E20: 7 | F20: 50 | G20: 50 | H20: 50 | I20: 40 | J20: =SUM(E20:I20)/5 -> 39.4 | K20: =((COUNTIF((E20:I20),"<50"))+(COUNTIF((E20:I20),"=A"))) -> 2 | L20: =IF((K20<1),"0","1") -> 1 | M20: =COUNTIF((E20:I20),"=A") -> 0 | N20: 98
... A24: 17 | B24: 111625201017 | C24: BAGAVATHI E | E24: 20 | F24: 33.333333 | G24: 17 | H24: 23 | I24: 60 | J24: =SUM(E24:I24)/5 -> 30.666667 | K24: =((COUNTIF((E24:I24),"<50"))+(COUNTIF((E24:I24),"=A"))) -> 4 | L24: =IF((K24<1),"0","1") -> 1 | M24: =COUNTIF((E24:I24),"=A") -> 0 | N24: 100
A25: 18 | B25: 111625201018 | C25: BALAJI T | E25: 67 | F25: 73.333333 | G25: 83 | H25: 33 | I25: 50 | J25: =SUM(E25:I25)/5 -> 61.266667 | K25: =((COUNTIF((E25:I25),"<50"))+(COUNTIF((E25:I25),"=A"))) -> 1 | N25: 100
A26: 19 | B26: 111625201019 | C26: BENARJI M | E26: 70 | F26: 50 | G26: 60 | H26: 30 | I26: 87 | J26: =SUM(E26:I26)/5 -> 59.4 | K26: =((COUNTIF((E26:I26),"<50"))+(COUNTIF((E26:I26),"=A"))) -> 1 | N26: 100
A27: 20 | B27: 111625201020 | C27: BHAVITH SAI REDDY B | E27: 73 | F27: 33.333333 | G27: 57 | H27: 63 | I27: 87 | J27: =SUM(E27:I27)/5 -> 62.666667 | K27: =((COUNTIF((E27:I27),"<50"))+(COUNTIF((E27:I27),"=A"))) -> 1 | N27: 100
A28: 21 | B28: 111625201021 | C28: BHOOMIKA P | E28: 90 | F28: 83.333333 | G28: 90 | H28: 80 | I28: 100 | J28: =SUM(E28:I28)/5 -> 88.666667 | K28: =((COUNTIF((E28:I28),"<50"))+(COUNTIF((E28:I28),"=A"))) -> 0 | N28: 96
A29: 22 | B29: 111625201022 | C29: BHUVANA LAKSHMI B | E29: 87 | F29: 66.666667 | G29: 70 | H29: 50 | I29: 97 | J29: =SUM(E29:I29)/5 -> 74.133333 | K29: =((COUNTIF((E29:I29),"<50"))+(COUNTIF((E29:I29),"=A"))) -> 0 | N29: 94
A30: 23 | B30: 111625201023 | C30: BHUVANESWARAN R | E30: 80 | F30: 86.666667 | G30: 70 | H30: 70 | I30: 67 | J30: =SUM(E30:I30)/5 -> 74.733333 | K30: =((COUNTIF((E30:I30),"<50"))+(COUNTIF((E30:I30),"=A"))) -> 0 | N30: 98
A31: 24 | B31: 111625201024 | C31: BUSIREDDY CHAITANYA | E31: 60 | F31: 33.333333 | G31: 40 | H31: 50 | I31: 63 | J31: =SUM(E31:I31)/5 -> 49.266667 | K31: =((COUNTIF((E31:I31),"<50"))+(COUNTIF((E31:I31),"=A"))) -> 2 | N31: 98
A32: 25 | B32: 111625201025 | C32: CHANDRU M | E32: 53 | F32: 53.333333 | G32: 33 | H32: 7 | I32: 57 | J32: =SUM(E32:I32)/5 -> 40.666667 | K32: =((COUNTIF((E32:I32),"<50"))+(COUNTIF((E32:I32),"=A"))) -> 2 | N32: 100
A33: 26 | B33: 111625201026 | C33: CHANDULURU VASAVI | E33: 87 | F33: 86.666667 | G33: 63 | H33: 50 | I33: 87 | J33: =SUM(E33:I33)/5 -> 74.733333 | K33: =((COUNTIF((E33:I33),"<50"))+(COUNTIF((E33:I33),"=A"))) -> 0 | N33: 100
A34: 27 | B34: 111625201027 | C34: CHATRESH B | E34: 57 | F34: 20 | G34: 70 | H34: 30 | I34: 80 | J34: =SUM(E34:I34)/5 -> 51.4 | K34: =((COUNTIF((E34:I34),"<50"))+(COUNTIF((E34:I34),"=A"))) -> 2 | N34: 87
A35: 28 | B35: 111625201028 | C35: DAKA VENKATA HARSHA VARDHAN REDDY | E35: 80 | F35: 53.333333 | G35: 57 | H35: 53 | I35: 93 | J35: =SUM(E35:I35)/5 -> 67.266667 | K35: =((COUNTIF((E35:I35),"<50"))+(COUNTIF((E35:I35),"=A"))) -> 0 | N35: 98
A36: 29 | B36: 111625201029 | C36: DEEKSHITHA S M | E36: 73 | F36: 73.333333 | G36: 70 | H36: 63 | I36: 80 | J36: =SUM(E36:I36)/5 -> 71.866667 | K36: =((COUNTIF((E36:I36),"<50"))+(COUNTIF((E36:I36),"=A"))) -> 0 | N36: 100
... A45: 38 | B45: 111625201038 | C45: DINESH N | E45: 50 | F45: 60 | G45: 57 | H45: 33 | I45: 70 | J45: =SUM(E45:I45)/5 -> 54 | K45: =((COUNTIF((E45:I45),"<50"))+(COUNTIF((E45:I45),"=A"))) -> 1 | N45: 100
A46: 39 | B46: 111625201039 | C46: DIVYA DHARSHINI C | E46: 97 | F46: A | G46: 90 | H46: 57 | I46: 60 | J46: =SUM(E46:I46)/5 -> 60.8 | K46: =((COUNTIF((E46:I46),"<50"))+(COUNTIF((E46:I46),"=A"))) -> 1 | N46: 91
A47: 40 | B47: 111625201040 | C47: DIVYA T | E47: 90 | F47: 90 | G47: 53 | H47: 84 | I47: 97 | J47: =SUM(E47:I47)/5 -> 82.8 | K47: =((COUNTIF((E47:I47),"<50"))+(COUNTIF((E47:I47),"=A"))) -> 0 | N47: 100
A48: 41 | B48: 111625201041 | C48: DONDETI BHARATH KUMAR REDDY | E48: 33 | F48: 53.333333 | G48: 50 | H48: 27 | I48: 80 | J48: =SUM(E48:I48)/5 -> 48.666667 | K48: =((COUNTIF((E48:I48),"<50"))+(COUNTIF((E48:I48),"=A"))) -> 2 | N48: 100
A49: 42 | B49: 111625201042 | C49: DONDETI REVANTH REDDY | E49: 60 | F49: 66.666667 | G49: 53 | H49: 9 | I49: 83 | J49: =SUM(E49:I49)/5 -> 54.333333 | K49: =((COUNTIF((E49:I49),"<50"))+(COUNTIF((E49:I49),"=A"))) -> 1 | L49: =IF((K49<1),"0","1") -> 1 | M49: =COUNTIF((E49:I49),"=A") -> 0 | N49: 100
A50: 43 | B50: 111625201043 | C50: DUVVURU DEEKSHITHA | E50: 73 | F50: 83.333333 | G50: 53 | H50: 52 | I50: 80 | J50: =SUM(E50:I50)/5 -> 68.266667 | K50: =((COUNTIF((E50:I50),"<50"))+(COUNTIF((E50:I50),"=A"))) -> 0 | L50: =IF((K50<1),"0","1") -> 0 | M50: =COUNTIF((E50:I50),"=A") -> 0 | N50: 98
A51: 44 | B51: 111625201044 | C51: GANESH PRASATH J | E51: 13 | F51: 33.333333 | G51: A | H51: 50 | I51: 63 | J51: =SUM(E51:I51)/5 -> 31.866667 | K51: =((COUNTIF((E51:I51),"<50"))+(COUNTIF((E51:I51),"=A"))) -> 3 | L51: =IF((K51<1),"0","1") -> 1 | M51: =COUNTIF((E51:I51),"=A") -> 1 | N51: 87
...

Sheet AIDS B
A1: R. M. K. COLLEGE OF ENGINEERING AND TECHNOLOGY
A2: R. S. M NAGAR, PUDUVOYAL - 601 206
A3: Department of Science and Humanities
A4: I Semester B.E (Academic Year : 2025-26)
A5: Unit Test - II Result Analysis
A6: Branch & Section: AIDS - B
A7: Sl. No. | B7: Reg. No. | C7: Name | D7: Cut off | E7: Maths | F7: Chem | G7: C++ | H7: SDP | I7: DPSD | J7: GPA | K7: No. of subjects failed | M7: absentees | N7: Attendance
A8: 1 | B8: 111625201063 | C8: JANANI B | E8: 98 | F8: 77 | G8: 96 | H8: 83.333333 | I8: 83 | J8: =SUM(E8:I8)/5 -> 87.466667 | K8: =((COUNTIF((E8:I8),"<50"))+(COUNTIF((E8:I8),"=A"))) -> 0 | L8: =IF((K8<1),"0","1") -> 0 | M8: =COUNTIF((E8:I8),"=A") -> 0 | N8: 98
A9: 2 | B9: 111625201064 | C9: JANANI S | E9: 81 | F9: 60 | G9: 63 | H9: A | I9: 63 | J9: =SUM(E9:I9)/5 -> 53.4 | K9: =((COUNTIF((E9:I9),"<50"))+(COUNTIF((E9:I9),"=A"))) -> 1 | L9: =IF((K9<1),"0","1") -> 1 | M9: =COUNTIF((E9:I9),"=A") -> 1 | N9: 94
A10: 3 | B10: 111625201065 | C10: JEEVARATHINAM M | E10: 50 | F10: 80 | G10: 36 | H10: 60 | I10: 73 | J10: =SUM(E10:I10)/5 -> 59.8 | K10: =((COUNTIF((E10:I10),"<50"))+(COUNTIF((E10:I10),"=A"))) -> 1 | L10: =IF((K10<1),"0","1") -> 1 | M10: =COUNTIF((E10:I10),"=A") -> 0 | N10: 98
A11: 4 | B11: 111625201066 | C11: JEFFRIN M | E11: 74 | F11: 90 | G11: 86 | H11: 90 | I11: 83 | J11: =SUM(E11:I11)/5 -> 84.6 | K11: =((COUNTIF((E11:I11),"<50"))+(COUNTIF((E11:I11),"=A"))) -> 0 | L11: =IF((K11<1),"0","1") -> 0 | M11: =COUNTIF((E11:I11),"=A") -> 0 | N11: 100
A12: 5 | B12: 111625201067 | C12: JERRIPOTHU VENKATA SAI KRISHNA | E12: 60 | F12: 73 | G12: 50 | H12: 26.666667 | I12: 43 | J12: =SUM(E12:I12)/5 -> 50.533333 | K12: =((COUNTIF((E12:I12),"<50"))+(COUNTIF((E12:I12),"=A"))) -> 2 | L12: =IF((K12<1),"0","1") -> 1 | M12: =COUNTIF((E12:I12),"=A") -> 0 | N12: 100
A13: 6 | B13: 111625201068 | C13: JYOSHITHA N M | E13: 12 | F13: 80 | G13: 23 | H13: 73.333333 | I13: 50 | J13: =SUM(E13:I13)/5 -> 47.666667 | K13: =((COUNTIF((E13:I13),"<50"))+(COUNTIF((E13:I13),"=A"))) -> 2 | L13: =IF((K13<1),"0","1") -> 1 | M13: =COUNTIF((E13:I13),"=A") -> 0 | N13: 100
A14: 7 | B14: 111625201069 | C14: KAILASH S | E14: 50 | F14: 50 | G14: 66 | H14: 60 | I14: 50 | J14: =SUM(E14:I14)/5 -> 55.2 | K14: =((COUNTIF((E14:I14),"<50"))+(COUNTIF((E14:I14),"=A"))) -> 0 | L14: =IF((K14<1),"0","1") -> 0 | M14: =COUNTIF((E14:I14),"=A") -> 0 | N14: 96
A15: 8 | B15: 111625201070 | C15: KAMALESH S | E15: 50 | F15: 53 | G15: 67 | H15: 16.666667 | I15: 50 | J15: =SUM(E15:I15)/5 -> 47.333333 | K15: =((COUNTIF((E15:I15),"<50"))+(COUNTIF((E15:I15),"=A"))) -> 1 | L15: =IF((K15<1),"0","1") -> 1 | M15: =COUNTIF((E15:I15),"=A") -> 0 | N15: 100
A16: 9 | B16: 111625201071 | C16: KAMESH H | E16: 50 | F16: 63 | G16: 37 | H16: 50 | I16: 50 | J16: =SUM(E16:I16)/5 -> 50 | K16: =((COUNTIF((E16:I16),"<50"))+(COUNTIF((E16:I16),"=A"))) -> 1 | L16: =IF((K16<1),"0","1") -> 1 | M16: =COUNTIF((E16:I16),"=A") -> 0 | N16: 100
A17: 10 | B17: 111625201072 | C17: KANCHARALA VENKATA MOHAN REDDDY | E17: 52 | F17: 50 | G17: 19 | H17: 36.666667 | I17: 50 | J17: =SUM(E17:I17)/5 -> 41.533333 | K17: =((COUNTIF((E17:I17),"<50"))+(COUNTIF((E17:I17),"=A"))) -> 2 | L17: =IF((K17<1),"0","1") -> 1 | M17: =COUNTIF((E17:I17),"=A") -> 0 | N17: 98
A18: 11 | B18: 111625201073 | C18: KANESKA S M | E18: 51 | F18: 53 | G18: 3 | H18: 50 | I18: 50 | J18: =SUM(E18:I18)/5 -> 41.4 | K18: =((COUNTIF((E18:I18),"<50"))+(COUNTIF((E18:I18),"=A"))) -> 1 | L18: =IF((K18<1),"0","1") -> 1 | M18: =COUNTIF((E18:I18),"=A") -> 0 | N18: 94
A19: 12 | B19: 111625201074 | C19: KANI MOZHI R | E19: 53 | F19: 87 | G19: 96 | H19: 83.333333 | I19: 77 | J19: =SUM(E19:I19)/5 -> 79.266667 | K19: =((COUNTIF((E19:I19),"<50"))+(COUNTIF((E19:I19),"=A"))) -> 0 | L19: =IF((K19<1),"0","1") -> 0 | M19: =COUNTIF((E19:I19),"=A") -> 0 | N19: 100
A20: 13 | B20: 111625201075 | C20: KASU RAKESH REDDY | E20: 54 | F20: 27 | G20: 16 | H20: 20 | I20: 3 | J20: =SUM(E20:I20)/5 -> 24 | K20: =((COUNTIF((E20:I20),"<50"))+(COUNTIF((E20:I20),"=A"))) -> 4 | L20: =IF((K20<1),"0","1") -> 1 | M20: =COUNTIF((E20:I20),"=A") -> 0 | N20: 98
A21: 14 | B21: 111625201076 | C21: KAVIARASI D | E21: 50 | F21: 50 | G21: 13 | H21: 66.666667 | I21: 50 | J21: =SUM(E21:I21)/5 -> 45.933333 | K21: =((COUNTIF((E21:I21),"<50"))+(COUNTIF((E21:I21),"=A"))) -> 1 | L21: =IF((K21<1),"0","1") -> 1 | M21: =COUNTIF((E21:I21),"=A") -> 0 | N21: 98
A22: 15 | B22: 111625201077 | C22: KAVIYA SRI V | E22: 88 | F22: 83 | G22: 83 | H22: 86.666667 | I22: 100 | J22: =SUM(E22:I22)/5 -> 88.133333 | K22: =((COUNTIF((E22:I22),"<50"))+(COUNTIF((E22:I22),"=A"))) -> 0 | L22: =IF((K22<1),"0","1") -> 0 | M22: =COUNTIF((E22:I22),"=A") -> 0 | N22: 100
A23: 16 | B23: 111625201078 | C23: KESAVARAJ S | E23: 56 | F23: 63 | G23: 80 | H23: 76.666667 | I23: 50 | J23: =SUM(E23:I23)/5 -> 65.133333 | K23: =((COUNTIF((E23:I23),"<50"))+(COUNTIF((E23:I23),"=A"))) -> 0 | N23: 100
A24: 17 | B24: 111625201079 | C24: KETHU BHUVANESWARI | E24: 74 | F24: 57 | G24: 50 | H24: 60 | I24: 73 | J24: =SUM(E24:I24)/5 -> 62.8 | K24: =((COUNTIF((E24:I24),"<50"))+(COUNTIF((E24:I24),"=A"))) -> 0 | N24: 100
A25: 18 | B25: 111625201080 | C25: KETHU JYOTHISWAR REDDY | E25: 95 | F25: 90 | G25: 87 | H25: 75 | I25: 53 | J25: =SUM(E25:I25)/5 -> 80 | K25: =((COUNTIF((E25:I25),"<50"))+(COUNTIF((E25:I25),"=A"))) -> 0 | N25: 94
A26: 19 | B26: 111625201081 | C26: KOLAMALA JAHNAVI | E26: 100 | F26: 83 | G26: 63 | H26: 83.333333 | I26: 97 | J26: =SUM(E26:I26)/5 -> 85.266667 | K26: =((COUNTIF((E26:I26),"<50"))+(COUNTIF((E26:I26),"=A"))) -> 0 | N26: 100
A27: 20 | B27: 111625201082 | C27: KOMMI SAI VARNIKA | E27: 52 | F27: 77 | G27: 26 | H27: 26.666667 | I27: 97 | J27: =SUM(E27:I27)/5 -> 55.733333 | K27: =((COUNTIF((E27:I27),"<50"))+(COUNTIF((E27:I27),"=A"))) -> 2 | N27: 100
A28: 21 | B28: 111625201083 | C28: KONDURU SUSMITHA | E28: 50 | F28: 63 | G28: 50 | H28: 80 | I28: 60 | J28: =SUM(E28:I28)/5 -> 60.6 | K28: =((COUNTIF((E28:I28),"<50"))+(COUNTIF((E28:I28),"=A"))) -> 0 | N28: 100
A29: 22 | B29: 111625201084 | C29: KOTA SAI CHARAN | E29: 11 | F29: 50 | G29: 0 | H29: 26.666667 | I29: 37 | J29: =SUM(E29:I29)/5 -> 24.933333 | K29: =((COUNTIF((E29:I29),"<50"))+(COUNTIF((E29:I29),"=A"))) -> 4 | N29: 100
A30: 23 | B30: 111625201085 | C30: KRISHKA M | E30: 53 | F30: 80 | G30: 76 | H30: 53.333333 | I30: 77 | J30: =SUM(E30:I30)/5 -> 67.866667 | K30: =((COUNTIF((E30:I30),"<50"))+(COUNTIF((E30:I30),"=A"))) -> 0 | N30: 98
A31: 24 | B31: 111625201086 | C31: LAKSHANIKA S T K | E31: 74 | F31: 77 | G31: 100 | H31: 83.333333 | I31: 97 | J31: =SUM(E31:I31)/5 -> 86.266667 | K31: =((COUNTIF((E31:I31),"<50"))+(COUNTIF((E31:I31),"=A"))) -> 0 | N31: 96
A32: 25 | B32: 111625201087 | C32: LAKSHMI NARAYANAN S B | E32: 60 | F32: 53 | G32: 50 | H32: 26.666667 | I32: 50 | J32: =SUM(E32:I32)/5 -> 47.933333 | K32: =((COUNTIF((E32:I32),"<50"))+(COUNTIF((E32:I32),"=A"))) -> 1 | N32: 98
A33: 26 | B33: 111625201088 | C33: LEKHA G | E33: 77 | F33: 87 | G33: 96 | H33: 76.666667 | I33: 100 | J33: =SUM(E33:I33)/5 -> 87.333333 | K33: =((COUNTIF((E33:I33),"<50"))+(COUNTIF((E33:I33),"=A"))) -> 0 | N33: 98
A34: 27 | B34: 111625201089 | C34: LEKKALA PRANATHI | E34: 74 | F34: 77 | G34: 73 | H34: 90 | I34: 67 | J34: =SUM(E34:I34)/5 -> 76.2 | K34: =((COUNTIF((E34:I34),"<50"))+(COUNTIF((E34:I34),"=A"))) -> 0 | N34: 100
... A39: 32 | B39: 111625201094 | C39: MADHAN KUMAR | E39: 88 | F39: 83 | G39: 90 | H39: 80 | I39: 80 | J39: =SUM(E39:I39)/5 -> 84.2 | K39: =((COUNTIF((E39:I39),"<50"))+(COUNTIF((E39:I39),"=A"))) -> 0 | N39: 100
A40: 33 | B40: 111625201095 | C40: MANOJ SAMUEL S | E40: 28 | F40: 60 | G40: A | H40: 26.666667 | I40: 23 | J40: =SUM(E40:I40)/5 -> 27.533333 | K40: =((COUNTIF((E40:I40),"<50"))+(COUNTIF((E40:I40),"=A"))) -> 4 | N40: 83
A41: 34 | B41: 111625201096 | C41: MELLAKANTI RUCHITHA | E41: 50 | F41: 63 | G41: 30 | H41: 20 | I41: 27 | J41: =SUM(E41:I41)/5 -> 38 | K41: =((COUNTIF((E41:I41),"<50"))+(COUNTIF((E41:I41),"=A"))) -> 3 | N41: 94
A42: 35 | B42: 111625201097 | C42: MOHAMED IRFAN I | E42: 60 | F42: 63 | G42: 53 | H42: 56.666667 | I42: 60 | J42: =SUM(E42:I42)/5 -> 58.533333 | K42: =((COUNTIF((E42:I42),"<50"))+(COUNTIF((E42:I42),"=A"))) -> 0 | N42: 98
A43: 36 | B43: 111625201098 | C43: MONISHA S | E43: 77 | F43: 83 | G43: 96 | H43: 76.666667 | I43: 50 | J43: =SUM(E43:I43)/5 -> 76.533333 | K43: =((COUNTIF((E43:I43),"<50"))+(COUNTIF((E43:I43),"=A"))) -> 0 | N43: 94
A44: 37 | B44: 111625201099 | C44: MUKESH S | E44: 51 | F44: 53 | G44: 50 | H44: 66.666667 | I44: A | J44: =SUM(E44:I44)/5 -> 44.133333 | K44: =((COUNTIF((E44:I44),"<50"))+(COUNTIF((E44:I44),"=A"))) -> 1 | L44: =IF((K44<1),"0","1") -> 1 | M44: =COUNTIF((E44:I44),"=A") -> 1 | N44: 89
...

Sheet AIDS C
A1: R. M. K. COLLEGE OF ENGINEERING AND TECHNOLOGY
A2: R. S. M NAGAR, PUDUVOYAL - 601 206
A3: Department of Science and Humanities
A4: I Semester B.E (Academic Year : 2025-26)
A5: Unit Test - II Result Analysis
A6: Branch & Section: AIDS - C
A7: Sl. No. | B7: Reg. No. | C7: Name | D7: Cut off | E7: Maths | F7: Chem | G7: C++ | H7: SDP | I7: DPSD | J7: GPA | K7: No. of subjects failed | M7: absentees | N7: Attendance
A8: 1 | B8: 111625201125 | C8: RADARAPU BABY JANANI | E8: 97 | F8: 76.666667 | G8: 77 | H8: 50 | I8: 83 | J8: =SUM(E8:I8)/5 -> 76.733333 | K8: =((COUNTIF((E8:I8),"<50"))+(COUNTIF((E8:I8),"=A"))) -> 0 | L8: =IF((K8<1),"0","1") -> 0 | M8: =COUNTIF((E8:I8),"=A") -> 0 | N8: 100
A9: 2 | B9: 111625201126 | C9: RAHUL K | E9: 20 | F9: 50 | G9: 74 | H9: 27 | I9: 30 | J9: =SUM(E9:I9)/5 -> 40.2 | K9: =((COUNTIF((E9:I9),"<50"))+(COUNTIF((E9:I9),"=A"))) -> 3 | L9: =IF((K9<1),"0","1") -> 1 | M9: =COUNTIF((E9:I9),"=A") -> 0 | N9: 98
A10: 3 | B10: 111625201127 | C10: RAJASRI G | E10: 70 | F10: 60 | G10: 63 | H10: 27 | I10: 93 | J10: =SUM(E10:I10)/5 -> 62.6 | K10: =((COUNTIF((E10:I10),"<50"))+(COUNTIF((E10:I10),"=A"))) -> 1 | L10: =IF((K10<1),"0","1") -> 1 | M10: =COUNTIF((E10:I10),"=A") -> 0 | N10: 94
A11: 4 | B11: 111625201128 | C11: RAMACHANDRAN G | E11: 77 | F11: 76.666667 | G11: 50 | H11: 70 | I11: 57 | J11: =SUM(E11:I11)/5 -> 66.133333 | K11: =((COUNTIF((E11:I11),"<50"))+(COUNTIF((E11:I11),"=A"))) -> 0 | L11: =IF((K11<1),"0","1") -> 0 | M11: =COUNTIF((E11:I11),"=A") -> 0 | N11: 100
A12: 5 | B12: 111625201129 | C12: RAMISETTY LASYA BHAVANI | E12: 30 | F12: 50 | G12: 27 | H12: 17 | I12: 63 | J12: =SUM(E12:I12)/5 -> 37.4 | K12: =((COUNTIF((E12:I12),"<50"))+(COUNTIF((E12:I12),"=A"))) -> 3 | L12: =IF((K12<1),"0","1") -> 1 | M12: =COUNTIF((E12:I12),"=A") -> 0 | N12: 100
A13: 6 | B13: 111625201130 | C13: RANJITH N B | E13: 73 | F13: 66.666667 | G13: 87 | H13: 87 | I13: 70 | J13: =SUM(E13:I13)/5 -> 76.733333 | K13: =((COUNTIF((E13:I13),"<50"))+(COUNTIF((E13:I13),"=A"))) -> 0 | L13: =IF((K13<1),"0","1") -> 0 | M13: =COUNTIF((E13:I13),"=A") -> 0 | N13: 100
A14: 7 | B14: 111625201131 | C14: RITHIKA J | E14: 73 | F14: 80 | G14: 83 | H14: 77 | I14: 93 | J14: =SUM(E14:I14)/5 -> 81.2 | K14: =((COUNTIF((E14:I14),"<50"))+(COUNTIF((E14:I14),"=A"))) -> 0 | L14: =IF((K14<1),"0","1") -> 0 | M14: =COUNTIF((E14:I14),"=A") -> 0 | N14: 100
A15: 8 | B15: 111625201132 | C15: RITU N | E15: 50 | F15: 63.333333 | G15: 67 | H15: 53 | I15: 67 | J15: =SUM(E15:I15)/5 -> 60.066667 | K15: =((COUNTIF((E15:I15),"<50"))+(COUNTIF((E15:I15),"=A"))) -> 0 | L15: =IF((K15<1),"0","1") -> 0 | M15: =COUNTIF((E15:I15),"=A") -> 0 | N15: 96
A16: 9 | B16: 111625201133 | C16: RUVANTHIKA S T K | E16: 80 | F16: 83.333333 | G16: 53 | H16: A | I16: 80 | J16: =SUM(E16:I16)/5 -> 59.266667 | K16: =((COUNTIF((E16:I16),"<50"))+(COUNTIF((E16:I16),"=A"))) -> 1 | L16: =IF((K16<1),"0","1") -> 1 | M16: =COUNTIF((E16:I16),"=A") -> 1 | N16: 94
A17: 10 | B17: 111625201134 | C17: SACHIN D | E17: 70 | F17: 63.333333 | G17: 70 | H17: A | I17: 50 | J17: =SUM(E17:I17)/5 -> 50.666667 | K17: =((COUNTIF((E17:I17),"<50"))+(COUNTIF((E17:I17),"=A"))) -> 1 | N17: 53
A18: 11 | B18: 111625201135 | C18: SAISHREYASH K S | E18: 57 | F18: 66.666667 | G18: 77 | H18: 60 | I18: 70 | J18: =SUM(E18:I18)/5 -> 66.133333 | K18: =((COUNTIF((E18:I18),"<50"))+(COUNTIF((E18:I18),"=A"))) -> 0 | N18: 100
A19: 12 | B19: 111625201136 | C19: SAM ELIJAH BG | E19: 87 | F19: 53.333333 | G19: 63 | H19: 50 | I19: 30 | J19: =SUM(E19:I19)/5 -> 56.666667 | K19: =((COUNTIF((E19:I19),"<50"))+(COUNTIF((E19:I19),"=A"))) -> 1 | N19: 98
A20: 13 | B20: 111625201137 | C20: SAM NICHOLAS H | E20: 20 | F20: 63.333333 | G20: 50 | H20: 50 | I20: 57 | J20: =SUM(E20:I20)/5 -> 48.066667 | K20: =((COUNTIF((E20:I20),"<50"))+(COUNTIF((E20:I20),"=A"))) -> 1 | N20: 91
A21: 14 | B21: 111625201138 | C21: SANCHITA V | E21: 100 | F21: 86.666667 | G21: 70 | H21: 57 | I21: 70 | J21: =SUM(E21:I21)/5 -> 76.733333 | K21: =((COUNTIF((E21:I21),"<50"))+(COUNTIF((E21:I21),"=A"))) -> 0 | N21: 87
A22: 15 | B22: 111625201139 | C22: SANDHIYA B | E22: 97 | F22: 80 | G22: 57 | H22: 50 | I22: 87 | J22: =SUM(E22:I22)/5 -> 74.2 | K22: =((COUNTIF((E22:I22),"<50"))+(COUNTIF((E22:I22),"=A"))) -> 0 | N22: 96
A23: 16 | B23: 111625201140 | C23: SANDHIYA V | E23: 77 | F23: 63.333333 | G23: 60 | H23: 50 | I23: 70 | J23: =SUM(E23:I23)/5 -> 64.066667 | K23: =((COUNTIF((E23:I23),"<50"))+(COUNTIF((E23:I23),"=A"))) -> 0 | N23: 100
A24: 17 | B24: 111625201141 | C24: SANGEETHA SRI R | E24: 60 | F24: 80 | G24: 77 | H24: 57 | I24: 70 | J24: =SUM(E24:I24)/5 -> 68.8 | K24: =((COUNTIF((E24:I24),"<50"))+(COUNTIF((E24:I24),"=A"))) -> 0 | N24: 96
A25: 18 | B25: 111625201142 | C25: SANJANA N | E25: 93 | F25: 90 | G25: 67 | H25: 73 | I25: 50 | J25: =SUM(E25:I25)/5 -> 74.6 | K25: =((COUNTIF((E25:I25),"<50"))+(COUNTIF((E25:I25),"=A"))) -> 0 | N25: 94
A26: 19 | B26: 111625201143 | C26: SANJAY SRIDHAR D A | E26: 60 | F26: 73.333333 | G26: 63 | H26: 51 | I26: 70 | J26: =SUM(E26:I26)/5 -> 63.466667 | K26: =((COUNTIF((E26:I26),"<50"))+(COUNTIF((E26:I26),"=A"))) -> 0 | N26: 98
A27: 20 | B27: 111625201144 | C27: SANJU SHREE G | E27: 73 | F27: 83.333333 | G27: 87 | H27: 50 | I27: 87 | J27: =SUM(E27:I27)/5 -> 76.066667 | K27: =((COUNTIF((E27:I27),"<50"))+(COUNTIF((E27:I27),"=A"))) -> 0 | N27: 96
A28: 21 | B28: 111625201145 | C28: SANTHOSH P | E28: 80 | F28: 60 | G28: 90 | H28: 33 | I28: 63 | J28: =SUM(E28:I28)/5 -> 65.2 | K28: =((COUNTIF((E28:I28),"<50"))+(COUNTIF((E28:I28),"=A"))) -> 1 | N28: 94
A29: 22 | B29: 111625201146 | C29: SARAVANAN B L | E29: 63 | F29: 76.666667 | G29: 37 | H29: 53 | I29: 13 | J29: =SUM(E29:I29)/5 -> 48.533333 | K29: =((COUNTIF((E29:I29),"<50"))+(COUNTIF((E29:I29),"=A"))) -> 2 | N29: 98
... A31: 24 | B31: 111625201148 | C31: SHAMREEN FATHIMA J | E31: 97 | F31: 83.333333 | G31: 90 | H31: 80 | I31: 83 | J31: =SUM(E31:I31)/5 -> 86.666667 | K31: =((COUNTIF((E31:I31),"<50"))+(COUNTIF((E31:I31),"=A"))) -> 0 | N31: 96
A32: 25 | B32: 111625201149 | C32: SHEETHAL S | E32: A | F32: A | G32: A | H32: A | I32: A | J32: =SUM(E32:I32)/5 -> 0 | K32: =((COUNTIF((E32:I32),"<50"))+(COUNTIF((E32:I32),"=A"))) -> 5 | N32: 87
A33: 26 | B33: 111625201150 | C33: SHIVANI M | E33: 87 | F33: 73.333333 | G33: 90 | H33: 73 | I33: 97 | J33: =SUM(E33:I33)/5 -> 84.066667 | K33: =((COUNTIF((E33:I33),"<50"))+(COUNTIF((E33:I33),"=A"))) -> 0 | N33: 100
A34: 27 | B34: 111625201151 | C34: SHREE DHARSHAN B R | E34: 80 | F34: 66.666667 | G34: 87 | H34: 57 | I34: 13 | J34: =SUM(E34:I34)/5 -> 60.733333 | K34: =((COUNTIF((E34:I34),"<50"))+(COUNTIF((E34:I34),"=A"))) -> 1 | N34: 98
A35: 28 | B35: 111625201152 | C35: SIVARUBAN K G | E35: 50 | F35: 30 | G35: 70 | H35: 37 | I35: 50 | J35: =SUM(E35:I35)/5 -> 47.4 | K35: =((COUNTIF((E35:I35),"<50"))+(COUNTIF((E35:I35),"=A"))) -> 2 | N35: 96
A36: 29 | B36: 111625201153 | C36: SOLLETI ANVITHA | E36: 90 | F36: 56.666667 | G36: 67 | H36: 53 | I36: 57 | J36: =SUM(E36:I36)/5 -> 64.733333 | K36: =((COUNTIF((E36:I36),"<50"))+(COUNTIF((E36:I36),"=A"))) -> 0 | N36: 100
A37: 30 | B37: 111625201154 | C37: SUBHASHINI K | E37: 90 | F37: 90 | G37: 93 | H37: 83 | I37: 63 | J37: =SUM(E37:I37)/5 -> 83.8 | K37: =((COUNTIF((E37:I37),"<50"))+(COUNTIF((E37:I37),"=A"))) -> 0 | N37: 98
A38: 31 | B38: 111625201155 | C38: SUMANTH S | E38: 77 | F38: 66.666667 | G38: 83 | H38: 57 | I38: 50 | J38: =SUM(E38:I38)/5 -> 66.733333 | K38: =((COUNTIF((E38:I38),"<50"))+(COUNTIF((E38:I38),"=A"))) -> 0 | L38: =IF((K38<1),"0","1") -> 0 | M38: =COUNTIF((E38:I38),"=A") -> 0 | N38: 100
A39: 32 | B39: 111625201156 | C39: SURENDHAR K | E39: 50 | F39: 73 | G39: 43 | H39: 13 | I39: 50 | J39: =SUM(E39:I39)/5 -> 45.8 | K39: =((COUNTIF((E39:I39),"<50"))+(COUNTIF((E39:I39),"=A"))) -> 2 | L39: =IF((K39<1),"0","1") -> 1 | M39: =COUNTIF((E39:I39),"=A") -> 0 | N39: 100
A40: 33 | B40: 111625201157 | C40: SYED AHMED BASHA | E40: 50 | F40: 50 | G40: 17 | H40: 33 | I40: 63 | J40: =SUM(E40:I40)/5 -> 42.6 | K40: =((COUNTIF((E40:I40),"<50"))+(COUNTIF((E40:I40),"=A"))) -> 2 | L40: =IF((K40<1),"0","1") -> 1 | M40: =COUNTIF((E40:I40),"=A") -> 0 | N40: 89
A41: 34 | B41: 111625201158 | C41: TEJA SAI C | E41: 93 | F41: 90 | G41: 83 | H41: 77 | I41: 70 | J41: =SUM(E41:I41)/5 -> 82.6 | K41: =((COUNTIF((E41:I41),"<50"))+(COUNTIF((E41:I41),"=A"))) -> 0 | L41: =IF((K41<1),"0","1") -> 0 | M41: =COUNTIF((E41:I41),"=A") -> 0 | N41: 100
...

Sheet Overall
A1: R.M.K.COLLEGE OF ENGINEERING AND TECHNOLOGY
A3: R.S.M. NAGAR, PUDUVOYAL - 601 206
A5: Batch: 17 Date: 4.10.24
A7: I Semester B.E (Academic Year : 2025-26)
A8: IAT1 Result Analysis
C12: Dept. | D12: STUDENTS APPEARED | E12: STUDENTS PASSED | F12: STUDENTS FAILED | G12: PASS %
C14: AIDS | D14: =(COUNT('AIDS A'!A8:A69)+COUNT('AIDS B'!A8:A69)+COUNT('AIDS C'!A8:A69)) -> 186 | E14: =D14-F14 -> 94 | F14: ='AIDS A'!E80+'AIDS B'!E80+'AIDS C'!E79 -> 92 | G14: =(E14/D14)*100 -> 50.537634
B16: No. of Failures(Dept.wise)
B17: Dept. | C17: Maths | D17: Chem | E17: C++ | F17: SDP | G17: DPSD | H17: Total
B18: AIDS | C18: ='AIDS A'!E75+'AIDS B'!E75+'AIDS A'!E73+'AIDS B'!E73+'AIDS C'!E74+'AIDS C'!E72 -> 24 | D18: ='AIDS A'!F75+'AIDS B'!F75+'AIDS A'!F73+'AIDS B'!F73+'AIDS C'!F74+'AIDS C'!F72 -> 24 | E18: ='AIDS A'!G75+'AIDS B'!G75+'AIDS A'!G73+'AIDS B'!G73+'AIDS C'!G74+'AIDS C'!G72 -> 42 | F18: ='AIDS A'!H75+'AIDS B'!H75+'AIDS A'!H73+'AIDS B'!H73+'AIDS C'!H74+'AIDS C'!H72 -> 63 | G18: ='AIDS A'!I75+'AIDS B'!I75+'AIDS A'!I73+'AIDS B'!I73+'AIDS C'!I74+'AIDS C'!I72 -> 27 | H18: =SUM(C18:G18) -> 180
B19: Failed only in | C19: ='AIDS A'!E77+'AIDS B'!E77+'AIDS C'!E76 -> 4 | D19: ='AIDS A'!F77+'AIDS B'!F77+'AIDS C'!F76 -> 3 | E19: ='AIDS A'!G77+'AIDS B'!G77+'AIDS C'!G76 -> 6 | F19: ='AIDS A'!H77+'AIDS B'!H77+'AIDS C'!H76 -> 20 | G19: ='AIDS A'!I77+'AIDS B'!I77+'AIDS C'!I76 -> 6 | H19: =SUM(C19:G19) -> 39
B22: Dept. | C22: One Sub. failures | D22: Two Sub. failures | E22: Three Sub. failures | F22: Four Sub. failures | G22: Five Sub. failures | H22: Total No. of subjects
B23: AIDS | C23: =(COUNTIF(('AIDS A'!K8:K69),"=1"))+(COUNTIF(('AIDS B'!K8:K69),"=1"))+(COUNTIF(('AIDS C'!K8:K69),"=1")) -> 39 | D23: =(COUNTIF(('AIDS A'!K8:K69),"=2"))+(COUNTIF(('AIDS B'!K8:K69),"=2"))+(COUNTIF(('AIDS C'!K8:K69),"=2")) -> 30 | E23: =(COUNTIF(('AIDS A'!K8:K69),"=3"))+(COUNTIF(('AIDS B'!K8:K69),"=3"))+(COUNTIF(('AIDS C'!K8:K69),"=3")) -> 13 | F23: =(COUNTIF(('AIDS A'!K8:K69),"=4"))+(COUNTIF(('AIDS B'!K8:K69),"=4"))+(COUNTIF(('AIDS C'!K8:K69),"=4")) -> 8 | G23: =(COUNTIF(('AIDS A'!K8:K69),"=5"))+(COUNTIF(('AIDS B'!K8:K69),"=5"))+(COUNTIF(('AIDS C'!K8:K69),"=5")) -> 2 | H23: =(C23*1)+(D23*2)+(E23*3)+(F23*4)+(G23*5) -> 180
